Traceback (most recent call last):
  File "/Users/sbello/Documents/personal_repos/notas_de_python/.venv/lib/python3.10/site-packages/jupyter_cache/executors/utils.py", line 51, in single_nb_execution
    executenb(
  File "/Users/sbello/Documents/personal_repos/notas_de_python/.venv/lib/python3.10/site-packages/nbclient/client.py", line 1204, in execute
    return NotebookClient(nb=nb, resources=resources, km=km, **kwargs).execute()
  File "/Users/sbello/Documents/personal_repos/notas_de_python/.venv/lib/python3.10/site-packages/nbclient/util.py", line 84, in wrapped
    return just_run(coro(*args, **kwargs))
  File "/Users/sbello/Documents/personal_repos/notas_de_python/.venv/lib/python3.10/site-packages/nbclient/util.py", line 62, in just_run
    return loop.run_until_complete(coro)
  File "/Users/sbello/.pyenv/versions/3.10.10/lib/python3.10/asyncio/base_events.py", line 649, in run_until_complete
    return future.result()
  File "/Users/sbello/Documents/personal_repos/notas_de_python/.venv/lib/python3.10/site-packages/nbclient/client.py", line 663, in async_execute
    await self.async_execute_cell(
  File "/Users/sbello/Documents/personal_repos/notas_de_python/.venv/lib/python3.10/site-packages/nbclient/client.py", line 965, in async_execute_cell
    await self._check_raise_for_error(cell, cell_index, exec_reply)
  File "/Users/sbello/Documents/personal_repos/notas_de_python/.venv/lib/python3.10/site-packages/nbclient/client.py", line 862, in _check_raise_for_error
    raise CellExecutionError.from_cell_and_msg(cell, exec_reply_content)
nbclient.exceptions.CellExecutionError: An error occurred while executing the following cell:
------------------
# Comprobacion de no creacion de atributo `lanzamiento` en consola_2
print(consola_2.lanzamiento)
------------------

[0;31m---------------------------------------------------------------------------[0m
[0;31mAttributeError[0m                            Traceback (most recent call last)
Cell [0;32mIn[8], line 2[0m
[1;32m      1[0m [38;5;66;03m# Comprobacion de no creacion de atributo `lanzamiento` en consola_2[39;00m
[0;32m----> 2[0m [38;5;28mprint[39m([43mconsola_2[49m[38;5;241;43m.[39;49m[43mlanzamiento[49m)

[0;31mAttributeError[0m: 'Consolas' object has no attribute 'lanzamiento'
AttributeError: 'Consolas' object has no attribute 'lanzamiento'

